<robot name="sub" version="1.0">
  <joint name="camera_link_joint" type="fixed">
    <origin rpy="0.00000 0.00000 0.00000" xyz="0.14000 0.00000 0.00000"/>
    <parent link="base_link"/>
    <child link="camera_link"/>
  </joint>
  <joint name="front_left_thruster_link_joint" type="fixed">
    <origin rpy="1.57080 0.00000 0.78540" xyz="0.20484 0.11067 0.00000"/>
    <parent link="base_link"/>
    <child link="front_left_thruster_link"/>
  </joint>
  <joint name="vertical_left_thruster_link_joint" type="fixed">
    <origin rpy="0.00000 0.00000 0.00000" xyz="0.00000 0.15925 0.03229"/>
    <parent link="base_link"/>
    <child link="vertical_left_thruster_link"/>
  </joint>
  <joint name="vertical_left_propeller_link_joint" type="revolute">
    <limit lower="-3.14000" upper="3.14000" effort="0.00000" velocity="0.00000"/>
    <origin rpy="0.00000 0.00000 0.00000" xyz="0.00000 0.00018 0.04451"/>
    <parent link="vertical_left_thruster_link"/>
    <child link="vertical_left_propeller_link"/>
    <axis xyz="0.00000 0.00000 1.00000"/>
  </joint>
  <joint name="vertical_right_thruster_link_joint" type="fixed">
    <origin rpy="0.00000 0.00000 0.00000" xyz="0.00000 -0.15925 0.03229"/>
    <parent link="base_link"/>
    <child link="vertical_right_thruster_link"/>
  </joint>
  <joint name="vertical_right_propeller_link_joint" type="revolute">
    <limit lower="-3.14000" upper="3.14000" effort="0.00000" velocity="0.00000"/>
    <origin rpy="0.00000 0.00000 0.00000" xyz="0.00000 0.00000 0.04451"/>
    <parent link="vertical_right_thruster_link"/>
    <child link="vertical_right_propeller_link"/>
    <axis xyz="0.00000 0.00000 1.00000"/>
  </joint>
  <joint name="front_left_propeller_link_joint" type="revolute">
    <limit lower="-3.14000" upper="3.14000" effort="0.00000" velocity="0.00000"/>
    <origin rpy="0.00000 -0.00000 0.00000" xyz="-0.00026 0.00000 0.04445"/>
    <parent link="front_left_thruster_link"/>
    <child link="front_left_propeller_link"/>
    <axis xyz="0.00000 0.00000 1.00000"/>
  </joint>
  <joint name="front_right_thruster_link_joint" type="fixed">
    <origin rpy="-1.57080 0.00000 -0.78540" xyz="0.20484 -0.11067 0.00000"/>
    <parent link="base_link"/>
    <child link="front_right_thruster_link"/>
  </joint>
  <joint name="front_right_propeller_link_joint" type="revolute">
    <limit lower="-3.14000" upper="3.14000" effort="0.00000" velocity="0.00000"/>
    <origin rpy="-0.00000 -0.00000 -0.00000" xyz="-0.00026 -0.00000 0.04445"/>
    <parent link="front_right_thruster_link"/>
    <child link="front_right_propeller_link"/>
    <axis xyz="0.00000 0.00000 1.00000"/>
  </joint>
  <joint name="imu_link_joint" type="fixed">
    <origin rpy="0.00000 0.00000 0.00000" xyz="-0.06000 0.00000 0.00000"/>
    <parent link="base_link"/>
    <child link="imu_link"/>
  </joint>
  <joint name="rear_left_thruster_link_joint" type="fixed">
    <origin rpy="-1.57080 0.00000 2.35619" xyz="-0.20484 0.11067 0.00000"/>
    <parent link="base_link"/>
    <child link="rear_left_thruster_link"/>
  </joint>
  <joint name="rear_left_propeller_link_joint" type="revolute">
    <limit lower="-3.14000" upper="3.14000" effort="0.00000" velocity="0.00000"/>
    <origin rpy="0.00000 0.00000 -0.00000" xyz="-0.00026 -0.00000 0.04445"/>
    <parent link="rear_left_thruster_link"/>
    <child link="rear_left_propeller_link"/>
    <axis xyz="0.00000 0.00000 1.00000"/>
  </joint>
  <joint name="rear_right_thruster_link_joint" type="fixed">
    <origin rpy="1.57080 0.00000 -2.35619" xyz="-0.20484 -0.11067 0.00000"/>
    <parent link="base_link"/>
    <child link="rear_right_thruster_link"/>
  </joint>
  <joint name="rear_right_propeller_link_joint" type="revolute">
    <limit lower="-3.14000" upper="3.14000" effort="0.00000" velocity="0.00000"/>
    <origin rpy="-0.00000 0.00000 0.00000" xyz="-0.00026 0.00000 0.04445"/>
    <parent link="rear_right_thruster_link"/>
    <child link="rear_right_propeller_link"/>
    <axis xyz="0.00000 0.00000 1.00000"/>
  </joint>
  <link name="base_link">
    <collision name="base_collision">
      <origin rpy="0.00000 0.00000 0.00000" xyz="0.00000 0.00000 0.00000"/>
      <geometry>
        <box size="0.30081 0.21589 0.20572"/>
      </geometry>
    </collision>
    <inertial>
      <inertia ixx="249.68401" ixy="0.00000" ixz="0.00000" iyy="356.19847" iyz="0.00000" izz="399.43128"/>
      <origin rpy="0.00000 0.00000 0.00000" xyz="0.00000 0.00000 0.00000"/>
      <mass value="3.00000"/>
    </inertial>
    <visual name="base">
      <material name="frame_material"/>
      <origin rpy="1.57080 0.00000 0.00000" xyz="0.00000 0.00000 0.00000"/>
      <geometry>
        <mesh filename="../meshes/stl/Basic Sub.stl" scale="1.00000 1.00000 1.00000"/>
      </geometry>
    </visual>
  </link>
  <link name="camera_link">
    <sensor name="camera_sensor" type="camera">
      <origin rpy="-0.00000 1.57080 0.00000" xyz="-0.00000 0.00000 0.00000"/>
      <parent link="camera_link"/>
      <camera>
        <image>
          <width>1280</width>
          <height>720</height>
          <hfov>1.57080</hfov>
        </image>
      </camera>
    </sensor>
  </link>
  <link name="rear_right_propeller_link">
    <inertial>
      <inertia ixx="0.00102" ixy="-0.00000" ixz="-0.00000" iyy="0.00102" iyz="0.00000" izz="0.00098"/>
      <origin rpy="0.00000 0.00000 0.00000" xyz="0.00043 0.00044 0.00006"/>
      <mass value="0.00050"/>
    </inertial>
    <visual name="rear_right_propeller">
      <material name="propeller_material"/>
      <origin rpy="-1.57080 0.00000 3.14159" xyz="0.00043 0.00044 0.00006"/>
      <geometry>
        <mesh filename="../meshes/stl/prop_40.008.stl" scale="1.00000 1.00000 1.00000"/>
      </geometry>
    </visual>
  </link>
  <link name="vertical_left_thruster_link">
    <collision name="vertical_left_thruster_collision">
      <origin rpy="0.00000 0.00000 0.00000" xyz="0.00000 0.00028 0.00000"/>
      <geometry>
        <cylinder radius="0.04181" length="0.14389"/>
      </geometry>
    </collision>
    <inertial>
      <inertia ixx="5.86360" ixy="0.00000" ixz="-0.00000" iyy="5.86360" iyz="-0.00000" izz="3.27121"/>
      <origin rpy="0.00000 0.00000 0.00000" xyz="0.00000 0.00028 -0.00000"/>
      <mass value="0.25000"/>
    </inertial>
    <visual name="vertical_left_thruster">
      <material name="thruster_material"/>
      <origin rpy="3.14159 0.00000 -1.57080" xyz="0.00000 0.00028 0.00000"/>
      <geometry>
        <mesh filename="../meshes/stl/Shroud.005.stl" scale="1.00000 1.00000 1.00000"/>
      </geometry>
    </visual>
  </link>
  <link name="vertical_left_propeller_link">
    <inertial>
      <inertia ixx="0.00098" ixy="-0.00000" ixz="0.00000" iyy="0.00102" iyz="0.00000" izz="0.00102"/>
      <origin rpy="0.00000 0.00000 0.00000" xyz="-0.00102 0.00055 0.00000"/>
      <mass value="0.00050"/>
    </inertial>
    <visual name="vertical_left_propeller">
      <material name="propeller_material"/>
      <origin rpy="-1.57080 0.00000 -1.57080" xyz="-0.00102 0.00055 0.00000"/>
      <geometry>
        <mesh filename="../meshes/stl/prop_40.stl" scale="1.00000 1.00000 1.00000"/>
      </geometry>
    </visual>
  </link>
  <link name="vertical_right_thruster_link">
    <collision name="vertical_right_thruster_collision">
      <origin rpy="0.00000 0.00000 0.00000" xyz="0.00000 0.00000 0.00000"/>
      <geometry>
        <cylinder radius="0.04181" length="0.14389"/>
      </geometry>
    </collision>
    <inertial>
      <inertia ixx="5.86360" ixy="0.00000" ixz="0.00000" iyy="5.86360" iyz="0.00000" izz="3.27121"/>
      <origin rpy="0.00000 0.00000 0.00000" xyz="0.00000 0.00000 -0.00000"/>
      <mass value="0.25000"/>
    </inertial>
    <visual name="vertical_right_thruster">
      <material name="thruster_material"/>
      <origin rpy="3.14159 -0.00000 1.57080" xyz="0.00000 0.00000 0.00000"/>
      <geometry>
        <mesh filename="../meshes/stl/Shroud.004.stl" scale="1.00000 1.00000 1.00000"/>
      </geometry>
    </visual>
  </link>
  <link name="vertical_right_propeller_link">
    <inertial>
      <inertia ixx="0.00098" ixy="-0.00000" ixz="-0.00000" iyy="0.00102" iyz="-0.00000" izz="0.00102"/>
      <origin rpy="0.00000 0.00000 0.00000" xyz="0.00058 -0.00018 0.00000"/>
      <mass value="0.00050"/>
    </inertial>
    <visual name="vertical_right_propeller">
      <material name="propeller_material"/>
      <origin rpy="-1.57080 0.00000 1.57080" xyz="0.00058 -0.00018 0.00000"/>
      <geometry>
        <mesh filename="../meshes/stl/prop_40.006.stl" scale="1.00000 1.00000 1.00000"/>
      </geometry>
    </visual>
  </link>
  <link name="front_left_thruster_link">
    <collision name="front_left_thruster_collision">
      <origin rpy="3.14159 0.00000 -3.14159" xyz="0.00043 -0.00000 -0.00680"/>
      <geometry>
        <cylinder radius="0.04181" length="0.14389"/>
      </geometry>
    </collision>
    <inertial>
      <inertia ixx="4.56741" ixy="1.29620" ixz="0.00000" iyy="4.56741" iyz="-0.00000" izz="5.86361"/>
      <origin rpy="0.00000 0.00000 0.00000" xyz="-0.00000 -0.00000 -0.00000"/>
      <mass value="0.25000"/>
    </inertial>
    <visual name="front_left_thruster">
      <material name="thruster_material"/>
      <origin rpy="-3.14159 -0.00000 -3.14159" xyz="-0.00000 0.00000 0.00000"/>
      <geometry>
        <mesh filename="../meshes/stl/Shroud.001.stl" scale="1.00000 1.00000 1.00000"/>
      </geometry>
    </visual>
  </link>
  <link name="front_left_propeller_link">
    <inertial>
      <inertia ixx="0.00102" ixy="-0.00000" ixz="0.00000" iyy="0.00102" iyz="-0.00000" izz="0.00098"/>
      <origin rpy="0.00000 0.00000 0.00000" xyz="-0.00014 0.00024 0.00019"/>
      <mass value="0.00050"/>
    </inertial>
    <visual name="front_left_propeller">
      <material name="propeller_material"/>
      <origin rpy="-1.57080 -0.00000 -3.14159" xyz="-0.00014 0.00024 0.00019"/>
      <geometry>
        <mesh filename="../meshes/stl/prop_40.009.stl" scale="1.00000 1.00000 1.00000"/>
      </geometry>
    </visual>
  </link>
  <link name="front_right_thruster_link">
    <collision name="front_right_thruster_collision">
      <origin rpy="-0.00000 0.00000 3.14159" xyz="0.00043 0.00000 -0.00680"/>
      <geometry>
        <cylinder radius="0.04181" length="0.14389"/>
      </geometry>
    </collision>
    <inertial>
      <inertia ixx="4.56741" ixy="-1.29620" ixz="0.00000" iyy="4.56741" iyz="0.00000" izz="5.86361"/>
      <origin rpy="0.00000 0.00000 0.00000" xyz="-0.00000 0.00000 0.00000"/>
      <mass value="0.25000"/>
    </inertial>
    <visual name="front_right_thruster">
      <material name="thruster_material"/>
      <origin rpy="3.14159 0.00000 3.14159" xyz="-0.00000 0.00000 0.00000"/>
      <geometry>
        <mesh filename="../meshes/stl/Shroud.stl" scale="1.00000 1.00000 1.00000"/>
      </geometry>
    </visual>
  </link>
  <link name="front_right_propeller_link">
    <inertial>
      <inertia ixx="0.00102" ixy="-0.00000" ixz="-0.00000" iyy="0.00102" iyz="-0.00000" izz="0.00098"/>
      <origin rpy="0.00000 0.00000 0.00000" xyz="-0.00072 0.00008 -0.00011"/>
      <mass value="0.00050"/>
    </inertial>
    <visual name="front_right_propeller">
      <material name="propeller_material"/>
      <origin rpy="-1.57080 0.00000 3.14159" xyz="-0.00072 0.00008 -0.00011"/>
      <geometry>
        <mesh filename="../meshes/stl/prop_40.010.stl" scale="1.00000 1.00000 1.00000"/>
      </geometry>
    </visual>
  </link>
  <link name="imu_link">
    <sensor name="imu_sensor" type="imu">
      <parent link="imu_link"/>
    </sensor>
  </link>
  <link name="rear_left_thruster_link">
    <collision name="rear_left_thruster_collision">
      <origin rpy="-0.00000 -0.00000 3.14159" xyz="0.00043 0.00000 -0.00680"/>
      <geometry>
        <cylinder radius="0.04181" length="0.14389"/>
      </geometry>
    </collision>
    <inertial>
      <inertia ixx="4.56741" ixy="-1.29620" ixz="0.00000" iyy="4.56741" iyz="0.00000" izz="5.86360"/>
      <origin rpy="0.00000 0.00000 0.00000" xyz="-0.00000 -0.00000 -0.00000"/>
      <mass value="0.25000"/>
    </inertial>
    <visual name="rear_left_thruster">
      <material name="thruster_material"/>
      <origin rpy="3.14159 -0.00000 3.14159" xyz="-0.00000 0.00000 -0.00000"/>
      <geometry>
        <mesh filename="../meshes/stl/Shroud.003.stl" scale="1.00000 1.00000 1.00000"/>
      </geometry>
    </visual>
  </link>
  <link name="rear_left_propeller_link">
    <inertial>
      <inertia ixx="0.00102" ixy="-0.00000" ixz="-0.00000" iyy="0.00102" iyz="0.00000" izz="0.00098"/>
      <origin rpy="0.00000 0.00000 0.00000" xyz="-0.00166 -0.00004 0.00027"/>
      <mass value="0.00050"/>
    </inertial>
    <visual name="rear_left_propeller">
      <material name="propeller_material"/>
      <origin rpy="-1.57080 0.00000 3.14159" xyz="-0.00166 -0.00004 0.00027"/>
      <geometry>
        <mesh filename="../meshes/stl/prop_40.007.stl" scale="1.00000 1.00000 1.00000"/>
      </geometry>
    </visual>
  </link>
  <link name="rear_right_thruster_link">
    <collision name="rear_right_thruster_collision">
      <origin rpy="-3.14159 -0.00000 -3.14159" xyz="0.00043 -0.00000 -0.00680"/>
      <geometry>
        <cylinder radius="0.04181" length="0.14389"/>
      </geometry>
    </collision>
    <inertial>
      <inertia ixx="4.56741" ixy="1.29620" ixz="0.00000" iyy="4.56741" iyz="-0.00000" izz="5.86360"/>
      <origin rpy="0.00000 0.00000 0.00000" xyz="-0.00000 0.00000 -0.00000"/>
      <mass value="0.25000"/>
    </inertial>
    <visual name="rear_right_thruster">
      <material name="thruster_material"/>
      <origin rpy="-3.14159 -0.00000 -3.14159" xyz="-0.00000 -0.00000 -0.00000"/>
      <geometry>
        <mesh filename="../meshes/stl/Shroud.002.stl" scale="1.00000 1.00000 1.00000"/>
      </geometry>
    </visual>
  </link>
  <material name="frame_material">
    <color rgba="0.09020 0.09020 0.09020 1.00000"/>
  </material>
  <material name="propeller_material">
    <color rgba="1.00000 0.89804 0.01569 1.00000"/>
  </material>
  <material name="thruster_material">
    <color rgba="0.64314 0.02353 0.07059 1.00000"/>
  </material>
</robot>